Workbook
Name _1: BD!$R$2:$R$39
Name _10: BD!$R$331:$R$375
Name _11: BD!$R$369:$R$412
Name _12: BD!$R$406:$R$450
Name _2: BD!$R$33:$R$74
Name _3: BD!$R$68:$R$112
Name _4: BD!$R$106:$R$149
Name _5: BD!$R$143:$R$187
Name _6: BD!$R$181:$R$224
Name _7: BD!$R$218:$R$262
Name _8: BD!$R$256:$R$300
Name _9: BD!$R$294:$R$337
Name Abastecimiento: BD!$J$2:$J$5
Name Administrativo: BD!$J$6:$J$8
Name Almacén: BD!$J$9:$J$11
Name Analista Administrativo: BD!$K$8
Name Analista de Abastecimiento: BD!$K$4:$K$5
Name Analista de Comercio Exterior: BD!$K$13
Name Analista de Gestión Humana: BD!$K$28
Name Analista de Impuestos: BD!$K$18
Name Analista de Inventarios: BD!$K$11
Name Analista de Laboratorio: BD!$K$36:$K$40
Name Analista de Mantenimiento: BD!$K$64
Name Analista de Mejoramiento Continuo: BD!$K$34
Name Analista HSEQ: BD!$K$33
Name Analista Tesorería: BD!$K$96
Name Aprendiz Contabilidad y Tesorería: BD!$K$15
Name Aprendiz Documentación: BD!$K$25
Name Aprendiz Eléctrico: BD!$K$52
Name Aprendiz Servicios Industriales OSBL: BD!$K$90
Name Aprendiz Soldadura: BD!$K$51
Name Asistente Administrativa: BD!$K$7
Name Asistente de Abastecimiento: BD!$K$3
Name Asistente de Contabilidad: BD!$K$17
Name Asistente de Gestión Humana: BD!$K$27
Name Asistente Documentación: BD!$K$26
Name Asistente Logístico: BD!$K$48:$K$49
Name Asistente TIC: BD!$K$98
Name Auxiliar de Almacén: BD!$K$9:$K$10
Name Auxiliar de Contabilidad: BD!$K$16
Name Auxiliar de Mantenimiento Mecánico: BD!$K$53
Name Auxiliar de Servicios Generales: BD!$K$72:$K$75
Name Auxiliar Financiero: BD!$K$68
Name Auxiliar HSEQ: BD!$K$31:$K$32
Name Auxiliar ISBL: BD!$K$76:$K$79
Name Auxiliar Servicios Generales Administrativo: BD!$K$6
Name Comercial: BD!$J$12
Name Comercio Exterior: BD!$J$13:$J$14
Name Conductor de Presidencia: BD!$K$70
Name Contabilidad: BD!$J$15:$J$19
Name Control Interno: BD!$J$20
Name Coordinador Comercial: BD!$K$12
Name Coordinador de Mantenimiento Eléctrico: BD!$K$65
Name Coordinador de Mantenimiento Mecánico: BD!$K$66
Name Coordinador de Producción: BD!$K$84:$K$87
Name Coordinadora Control Interno: BD!$K$20
Name Coordinadora de Aseguramiento de Calidad: BD!$K$41
Name Dir. Abastecimiento y Comercialización: BD!$J$21
Name Dir. de Planta: BD!$J$24
Name Dir. Financiera y Administrativa: BD!$J$22

Sheet Alimentación
A1: Fecha | B1: Dirección | C1: Área | D1: Cargo | E1: Nombre del colaborador | F1: Tipo de alimento | G1: Centro de costos | H1: Motivo | I1: Observación | J1: ="_"&MONTH(TODAY()) -> _10
A2: 45948 | B2: Dirección Financiera y Administrativa | C2: TIC | D2: Jefe TIC | E2: Juan Bolaño | F2: Cena | G2: =IF(C2="","",IFERROR(VLOOKUP(C2,BD!D:F,2,0),"")) -> 140301 | H2: Otro motivo
A3: 45948 | B3: Dirección Financiera y Administrativa | C3: TIC | D3: Asistente TIC | E3: Jose Angulo | F3: Cena | G3: =IF(C3="","",IFERROR(VLOOKUP(C3,BD!D:F,2,0),"")) -> 140301 | H3: Otro motivo
A4: 45948 | B4: Dirección Financiera y Administrativa | C4: TIC | E4: Andres Avila | F4: Cena | G4: =IF(C4="","",IFERROR(VLOOKUP(C4,BD!D:F,2,0),"")) -> 140301 | H4: Otro motivo
G5: =IF(C5="","",IFERROR(VLOOKUP(C5,BD!D:F,2,0),""))
G6: =IF(C6="","",IFERROR(VLOOKUP(C6,BD!D:F,2,0),""))
G7: =IF(C7="","",IFERROR(VLOOKUP(C7,BD!D:F,2,0),""))
G8: =IF(C8="","",IFERROR(VLOOKUP(C8,BD!D:F,2,0),""))
G9: =IF(C9="","",IFERROR(VLOOKUP(C9,BD!D:F,2,0),""))
G10: =IF(C10="","",IFERROR(VLOOKUP(C10,BD!D:F,2,0),""))
G11: =IF(C11="","",IFERROR(VLOOKUP(C11,BD!D:F,2,0),""))
G12: =IF(C12="","",IFERROR(VLOOKUP(C12,BD!D:F,2,0),""))
G13: =IF(C13="","",IFERROR(VLOOKUP(C13,BD!D:F,2,0),""))
G14: =IF(C14="","",IFERROR(VLOOKUP(C14,BD!D:F,2,0),""))
G15: =IF(C15="","",IFERROR(VLOOKUP(C15,BD!D:F,2,0),""))
G16: =IF(C16="","",IFERROR(VLOOKUP(C16,BD!D:F,2,0),""))
... G100: =IF(C100="","",IFERROR(VLOOKUP(C100,BD!D:F,2,0),""))

Sheet Transporte
A1: Fecha | B1: Dirección | C1: Área | D1: Cargo | E1: Nombre del colaborador | F1: Origen y destino | G1: Centro de costos | H1: Motivo | I1: Observación | J1: ="_"&MONTH(TODAY()) -> _10
A2: 45948 | B2: Dirección Financiera y Administrativa | C2: TIC | D2: Jefe TIC | E2: Juan Bolaño | F2: Origen: Bgreen - Destino: Casa | G2: =IF(C2="","",IFERROR(VLOOKUP(C2,BD!D:F,2,0),"")) -> 140301 | H2: Otro motivo
G3: =IF(C3="","",IFERROR(VLOOKUP(C3,BD!D:F,2,0),""))
G4: =IF(C4="","",IFERROR(VLOOKUP(C4,BD!D:F,2,0),""))
G5: =IF(C5="","",IFERROR(VLOOKUP(C5,BD!D:F,2,0),""))
G6: =IF(C6="","",IFERROR(VLOOKUP(C6,BD!D:F,2,0),""))
G7: =IF(C7="","",IFERROR(VLOOKUP(C7,BD!D:F,2,0),""))
G8: =IF(C8="","",IFERROR(VLOOKUP(C8,BD!D:F,2,0),""))
G9: =IF(C9="","",IFERROR(VLOOKUP(C9,BD!D:F,2,0),""))
G10: =IF(C10="","",IFERROR(VLOOKUP(C10,BD!D:F,2,0),""))
G11: =IF(C11="","",IFERROR(VLOOKUP(C11,BD!D:F,2,0),""))
G12: =IF(C12="","",IFERROR(VLOOKUP(C12,BD!D:F,2,0),""))
G13: =IF(C13="","",IFERROR(VLOOKUP(C13,BD!D:F,2,0),""))
G14: =IF(C14="","",IFERROR(VLOOKUP(C14,BD!D:F,2,0),""))
... G100: =IF(C100="","",IFERROR(VLOOKUP(C100,BD!D:F,2,0),""))

Sheet BD
A1: Dirección resumen | C1: Dirección | D1: Área | E1: C. de costos Alimentación | F1: C. de costos Taxis | H1: Dirección | I1: Área | J1: Cargo | K1: Nombre | M1: Tipo de alimento | N1: Origen y destino | O1: Motivo | Q1: Mes | R1: Fecha
A2: Dirección de Planta | C2: Dirección Abastecimiento y Comercialización | D2: Abastecimiento | E2: 130201 | F2: 130201 | H2: Dirección Abastecimiento y Comercialización | I2: Abastecimiento | J2: Mensajero | K2: Armando Valencia Leyva | M2: Desayuno | N2: Origen: Casa - Destino: Bgreen | O2: Parada de planta | Q2: 1 | R2: 45658
A3: Dirección Abastecimiento y Comercialización | C3: Dirección Abastecimiento y Comercialización | D3: Almacén | E3: 130501 | F3: 130501 | H3: Dirección Abastecimiento y Comercialización | I3: Abastecimiento | J3: Asistente de Abastecimiento | K3: Andrea Carolina Mejía Cantillo | M3: Almuerzo | N3: Origen: Bgreen - Destino: Casa | O3: Cobertura por novedades de personal (Incapacidad, vacaciones, entre otros) | Q3: 1 | R3: 45659
A4: Dirección Laboratorio y SIG | C4: Dirección Abastecimiento y Comercialización | D4: Comercial | E4: 130101 | F4: 130101 | H4: Dirección Abastecimiento y Comercialización | I4: Abastecimiento | J4: Analista de Abastecimiento | K4: Jorge Mario Maestre Peña | M4: Cena | N4: Origen: Bgreen - Destino: OLC | O4: Visita / Reunión | Q4: 1 | R4: 45660
A5: Dirección Financiera y Administrativa | C5: Dirección Abastecimiento y Comercialización | D5: Comercio Exterior | E5: 130302 | F5: 130302 | H5: Dirección Abastecimiento y Comercialización | I5: Abastecimiento | J5: Analista de Abastecimiento | K5: Sandra Victoria Gutiérrez Caro | N5: Origen: OLC - Destino: Bgreen | O5: Capacitación | Q5: 1 | R5: 45661
A6: Presidencia | C6: Dirección Abastecimiento y Comercialización | D6: Logística | E6: 130404 | F6: 130404 | H6: Dirección Financiera y Administrativa | I6: Administrativo | J6: Auxiliar Servicios Generales Administrativo | K6: Lucely Libet Cardona Ángel | N6: Otro | O6: Auditoría | Q6: 1 | R6: 45662
C7: Dirección Abastecimiento y Comercialización | D7: Dir. Abastecimiento y Comercialización | E7: 130001 | F7: 130001 | H7: Dirección Financiera y Administrativa | I7: Administrativo | J7: Asistente Administrativa | K7: Nuris María Delaytz Cabas | O7: Extensión de horario por operación | Q7: 1 | R7: 45663
C8: Dirección de Planta | D8: Mantenimiento | E8: 120326 | F8: 120326 | H8: Dirección Financiera y Administrativa | I8: Administrativo | J8: Analista Administrativo | K8: Diana Carolina Pardo Fernández | O8: Otro motivo | Q8: 1 | R8: 45664
C9: Dirección de Planta | D9: Producción | E9: 120108 | F9: 120108 | H9: Dirección Abastecimiento y Comercialización | I9: Almacén | J9: Auxiliar de Almacén | K9: Gonzalo Manuel Urueta Salazar | Q9: 1 | R9: 45665
C10: Dirección de Planta | D10: Servicios Industriales | E10: 120411 | F10: 120411 | H10: Dirección Abastecimiento y Comercialización | I10: Almacén | J10: Auxiliar de Almacén | K10: Jaime Sierra | Q10: 1 | R10: 45666
C11: Dirección de Planta | D11: Dir. de Planta | E11: 120001 | F11: 120001 | H11: Dirección Abastecimiento y Comercialización | I11: Almacén | J11: Analista de Inventarios | K11: Ioscar Gutiérrez Montenegro | Q11: 1 | R11: 45667
C12: Dirección Financiera y Administrativa | D12: Administrativo | E12: 150201 | F12: 150201 | H12: Dirección Abastecimiento y Comercialización | I12: Comercial | J12: Coordinador Comercial | K12: Julián Andrés Vecino Acelas | Q12: 1 | R12: 45668
C13: Dirección Financiera y Administrativa | D13: Contabilidad | E13: 160201 | F13: 160201 | H13: Dirección Abastecimiento y Comercialización | I13: Comercio Exterior | J13: Analista de Comercio Exterior | K13: Mabel Cantillo Machado | Q13: 1 | R13: 45669
C14: Dirección Financiera y Administrativa | D14: Gestión Humana | E14: 150101 | F14: 150101 | H14: Dirección Abastecimiento y Comercialización | I14: Comercio Exterior | J14: Jefe de Comercio Exterior e Inventarios | K14: Andrea Carolina Petro Doria | Q14: 1 | R14: 45670
C15: Dirección Financiera y Administrativa | D15: Planeación Financiera | E15: 160101 | F15: 160101 | H15: Dirección Financiera y Administrativa | I15: Contabilidad | J15: Aprendiz Contabilidad y Tesorería | K15: Natalia Michelle Yepez Hernandez | Q15: 1 | R15: 45671
C16: Dirección Financiera y Administrativa | D16: Tesorería | E16: 160301 | F16: 160301 | H16: Dirección Financiera y Administrativa | I16: Contabilidad | J16: Auxiliar de Contabilidad | K16: Dilan Alexander Joiro Ayala | Q16: 1 | R16: 45672
C17: Dirección Financiera y Administrativa | D17: TIC | E17: 140301 | F17: 140301 | H17: Dirección Financiera y Administrativa | I17: Contabilidad | J17: Asistente de Contabilidad | K17: Lila Sofía Villalba Meriño | Q17: 1 | R17: 45673
C18: Dirección Financiera y Administrativa | D18: Dir. Financiera y Administrativa | E18: 160001 | F18: 160001 | H18: Dirección Financiera y Administrativa | I18: Contabilidad | J18: Analista de Impuestos | K18: Ana Karina Castillo Mosquera | Q18: 1 | R18: 45674
C19: Dirección Laboratorio y SIG | D19: Gestión Documental | E19: 140209 | F19: 140209 | H19: Dirección Financiera y Administrativa | I19: Contabilidad | J19: Jefe de Contabilidad | K19: Katia Angélica Serrano Roa | Q19: 1 | R19: 45675
C20: Dirección Laboratorio y SIG | D20: HSEQ | E20: 140210 | F20: 140210 | H20: Presidencia | I20: Control Interno | J20: Coordinadora Control Interno | K20: María del Pilar Fontalvo Rodríguez | Q20: 1 | R20: 45676
... C24: Presidencia | D24: Presidencia | E24: 110002 | F24: 110002 | H24: Dirección de Planta | I24: Dir. de Planta | J24: Director de Planta | K24: Carlos Vásquez Osorio | Q24: 1 | R24: 45680
H25: Dirección Laboratorio y SIG | I25: Gestión Documental | J25: Aprendiz Documentación | Q25: 1 | R25: 45681
H26: Dirección Laboratorio y SIG | I26: Gestión Documental | J26: Asistente Documentación | K26: Yarelis Zuleth Reyes Berrío | Q26: 1 | R26: 45682
H27: Dirección Financiera y Administrativa | I27: Gestión Humana | J27: Asistente de Gestión Humana | K27: Elizabeth Orozco González | Q27: 1 | R27: 45683
H28: Dirección Financiera y Administrativa | I28: Gestión Humana | J28: Analista de Gestión Humana | K28: Nelys Esther Ropero Durán | Q28: 1 | R28: 45684
H29: Dirección Financiera y Administrativa | I29: Gestión Humana | J29: Jefe de Gestión Humana y Administrativo | K29: Daniela Lacouture Castillo | Q29: 1 | R29: 45685
H30: Dirección Laboratorio y SIG | I30: HSEQ | J30: Operario de Servicios Generales | K30: Zamir Ortiz Gutiérrez | Q30: 1 | R30: 45686
H31: Dirección Laboratorio y SIG | I31: HSEQ | J31: Auxiliar HSEQ | K31: Norchelys Carolina Barros Rusinque | Q31: 1 | R31: 45687
H32: Dirección Laboratorio y SIG | I32: HSEQ | J32: Auxiliar HSEQ | Q32: 1 | R32: 45688
H33: Dirección Laboratorio y SIG | I33: HSEQ | J33: Analista HSEQ | K33: Sergio Andrés Cantillo Polo | Q33: 1 | R33: 45689
H34: Dirección Laboratorio y SIG | I34: HSEQ | J34: Analista de Mejoramiento Continuo | K34: Oscar De Jesús Carrascal López | Q34: 1 | R34: 45690
H35: Dirección Laboratorio y SIG | I35: HSEQ | J35: Jefe HSEQ | K35: Karel Naniuska Vásquez Núñez | Q35: 1 | R35: 45691
H36: Dirección Laboratorio y SIG | I36: Laboratorio | J36: Analista de Laboratorio | K36: Jessica Paola León Díaz | Q36: 1 | R36: 45692
H37: Dirección Laboratorio y SIG | I37: Laboratorio | J37: Analista de Laboratorio | K37: Danis Andrés Solano Coronado | Q37: 1 | R37: 45693
H38: Dirección Laboratorio y SIG | I38: Laboratorio | J38: Analista de Laboratorio | K38: Wooedy Rosner Watson Salcedo | Q38: 1 | R38: 45694
H39: Dirección Laboratorio y SIG | I39: Laboratorio | J39: Analista de Laboratorio | K39: Edgar Justin Peláez Taborda | Q39: 1 | R39: 45695
H40: Dirección Laboratorio y SIG | I40: Laboratorio | J40: Analista de Laboratorio | Q40: 2 | R40: 45689
H41: Dirección Laboratorio y SIG | I41: Laboratorio | J41: Coordinadora de Aseguramiento de Calidad | K41: Marcela Bernal Galindo | Q41: 2 | R41: 45690
H42: Dirección Laboratorio y SIG | I42: Laboratorio | J42: Jefe de Control de Calidad | K42: Ligia María Ochoa Herrera | Q42: 2 | R42: 45691
H43: Dirección Abastecimiento y Comercialización | I43: Logística | J43: Operario Cargue y Descargue | K43: John Henry Rojas Prada | Q43: 2 | R43: 45692
...
